<?xml version="1.0"?>
<robot name="/home/daniel/ros2_ws/src/third_webots_pkg/resource/robot_model.urdf" xmlns:xacro="http://ros.org/wiki/xacro">
  <link name="base_link">
    <visual>
      <origin xyz="0 0 0.0415" rpy="0 0 0"/>
      <geometry>
        <cylinder radius="0.045" length="0.08"/>
      </geometry>
    </visual>
    <collision>
      <origin xyz="0 0 0.0415" rpy="0 0 0"/>
      <geometry>
        <cylinder radius="0.045" length="0.08"/>
      </geometry>
    </collision>
  </link>
  <link name="ds1">
  </link>
  <joint name="base_link_ds1_joint" type="fixed">
    <parent link="base_link"/>
    <child link="ds1"/>
    <origin xyz="0.042 -0.02 0.063" rpy="0 0 -0.5236"/>
  </joint>
  <link name="ds0">
  </link>
  <joint name="base_link_ds0_joint" type="fixed">
    <parent link="base_link"/>
    <child link="ds0"/>
    <origin xyz="0.042 0.02 0.063" rpy="0 0 0.5236"/>
  </joint>
  <joint name="right wheel motor" type="continuous">
    <parent link="base_link"/>
    <child link="right wheel"/>
    <axis xyz="0 1 0"/>
    <limit effort="10" velocity="10"/>
    <origin xyz="0 0 0.015" rpy="0 0 0"/>
  </joint>
  <link name="right wheel">
    <visual>
      <origin xyz="0 -0.045 0" rpy="1.5708 0 0"/>
      <geometry>
        <cylinder radius="0.025" length="0.01"/>
      </geometry>
    </visual>
    <collision>
      <origin xyz="0 -0.045 0" rpy="1.5708 0 0"/>
      <geometry>
        <cylinder radius="0.025" length="0.01"/>
      </geometry>
    </collision>
  </link>
  <joint name="left wheel motor" type="continuous">
    <parent link="base_link"/>
    <child link="left wheel"/>
    <axis xyz="0 1 0"/>
    <limit effort="10" velocity="10"/>
    <origin xyz="0 -0.045 0.015" rpy="0 0 0"/>
  </joint>
  <link name="left wheel">
    <visual>
      <origin xyz="0 0.045 0" rpy="1.5708 0 0"/>
      <geometry>
        <cylinder radius="0.025" length="0.01"/>
      </geometry>
    </visual>
    <collision>
      <origin xyz="0 0.045 0" rpy="1.5708 0 0"/>
      <geometry>
        <cylinder radius="0.025" length="0.01"/>
      </geometry>
    </collision>
  </link>
  <link name="top lidar">
  </link>
  <joint name="base_link_top lidar_joint" type="fixed">
    <parent link="base_link"/>
    <child link="top lidar"/>
    <origin xyz="0.04 0.045 0.09" rpy="0 0 0"/>
  </joint>
  <joint name="hingejoint" type="continuous">
    <parent link="base_link"/>
    <child link="rear caster wheel"/>
    <axis xyz="0 1 0"/>
    <origin xyz="0.03 0 0.005" rpy="0 0.003543 0"/>
  </joint>
  <link name="rear caster wheel">
    <visual>
      <origin xyz="-0.06 0 0" rpy="1.57 0 0"/>
      <geometry>
        <sphere radius="0.015"/>
      </geometry>
    </visual>
    <collision>
      <origin xyz="-0.06 0 0" rpy="1.57 0 0"/>
      <geometry>
        <sphere radius="0.015"/>
      </geometry>
    </collision>
  </link>
  <joint name="hingejoint_0" type="continuous">
    <parent link="base_link"/>
    <child link="front caster wheel"/>
    <axis xyz="0 1 0"/>
    <origin xyz="-0.03 0 0.005" rpy="0 0 0"/>
  </joint>
  <link name="front caster wheel">
    <visual>
      <origin xyz="0 0 0" rpy="1.57 0 0"/>
      <geometry>
        <sphere radius="0.015"/>
      </geometry>
    </visual>
    <collision>
      <origin xyz="0 0 0" rpy="1.57 0 0"/>
      <geometry>
        <sphere radius="0.015"/>
      </geometry>
    </collision>
  </link>
  <link name="imu">
  </link>
  <joint name="base_link_imu_joint" type="fixed">
    <parent link="base_link"/>
    <child link="imu"/>
    <origin xyz="0 0 0.082" rpy="0 0 0"/>
  </joint>
</robot>
