#VRML_SIM R2025a utf8

EXTERNPROTO "https://raw.githubusercontent.com/cyberbotics/webots/R2022b/projects/objects/backgrounds/protos/TexturedBackground.proto"
EXTERNPROTO "https://raw.githubusercontent.com/cyberbotics/webots/R2022b/projects/objects/backgrounds/protos/TexturedBackgroundLight.proto"
EXTERNPROTO "https://raw.githubusercontent.com/cyberbotics/webots/R2022b/projects/objects/floors/protos/CircleArena.proto"
EXTERNPROTO "https://raw.githubusercontent.com/cyberbotics/webots/R2025a/projects/objects/cabinet/protos/Cabinet.proto"
EXTERNPROTO "https://raw.githubusercontent.com/cyberbotics/webots/R2025a/projects/appearances/protos/PaintedWood.proto"
EXTERNPROTO "https://raw.githubusercontent.com/cyberbotics/webots/R2025a/projects/objects/plants/protos/PottedTree.proto"
EXTERNPROTO "https://raw.githubusercontent.com/cyberbotics/webots/R2025a/projects/objects/plants/protos/FlowerPot.proto"
EXTERNPROTO "https://raw.githubusercontent.com/cyberbotics/webots/R2025a/projects/objects/apartment_structure/protos/Wall.proto"
EXTERNPROTO "https://raw.githubusercontent.com/cyberbotics/webots/R2025a/projects/appearances/protos/Roughcast.proto"
EXTERNPROTO "https://raw.githubusercontent.com/cyberbotics/webots/R2025a/projects/objects/apartment_structure/protos/Radiator.proto"

WorldInfo {
  basicTimeStep 20
}
Viewpoint {
  orientation 0.051835038546363114 0.051430976263556534 0.9973304284235363 4.647827628038674
  position 0.030690207397622682 0.2175622214603855 -0.0037940317602723587
  follow "my_robot"
}
TexturedBackground {
}
TexturedBackgroundLight {
}
CircleArena {
  radius 4
  wallHeight 0.6
}
Wall {
  translation 3.21 0.9 0.250003
  rotation 1 0 0 1.5708
  size 0.2 0.5 2.4
  appearance Roughcast {
    colorOverride 0.988235 0.686275 0.243137
    textureTransform TextureTransform {
      scale 2.4 1
    }
  }
}
Wall {
  translation 1.01 3.1 0.510006
  rotation -0.5773509358554485 0.5773489358556708 0.5773509358554485 -2.094395307179586
  name "wall(1)"
  appearance Roughcast {
    colorOverride 0.988235 0.686275 0.243137
    textureTransform TextureTransform {
      scale 2.4 1
    }
  }
}
Wall {
  translation 3.31 -1.67 0.259995
  rotation -0.5773509358554485 0.5773489358556708 0.5773509358554485 -2.094395307179586
  name "wall(2)"
  size 0.2 0.5 4.4
  appearance Roughcast {
    colorOverride 0.988235 0.686275 0.243137
    textureTransform TextureTransform {
      scale 2.4 1
    }
  }
}
FlowerPot {
  translation 2.56 0.64 0
}
PottedTree {
  translation 0 -0.5 0
}
PottedTree {
  translation -2.38 -2.19 0
  name "potted tree(1)"
}
Cabinet {
  translation 3 0 0
  rotation 0 0 1 3.14159
  primaryAppearance PaintedWood {
    colorOverride 0.388235 0.270588 0.172549
  }
  secondaryAppearance PaintedWood {
    colorOverride 0.52549 0.368627 0.235294
  }
}
Robot {
  children [
    HingeJoint {
      jointParameters HingeJointParameters {
        axis 0 1 0
        anchor 0.03 0 0.005
        springConstant 0.05
      }
      endPoint Solid {
        translation 0.03 0 0.005
        children [
          DEF CASTER Pose {
            rotation 1 0 0 1.57
            children [
              Shape {
                appearance PBRAppearance {
                  baseColor 0.6 0.6 0.6
                  roughness 1
                  metalness 0
                }
                geometry Sphere {
                  radius 0.005
                }
              }
            ]
          }
        ]
        name "front caster wheel"
        boundingObject USE CASTER
        physics Physics {
        }
      }
    }
    HingeJoint {
      jointParameters HingeJointParameters {
        axis 0 1 0
        anchor 0.03 0 0.005
        springConstant 0.05
      }
      endPoint Solid {
        translation -0.03 0 0.005
        children [
          USE CASTER
        ]
        name "rear caster wheel"
        boundingObject USE CASTER
        physics Physics {
        }
      }
    }
    Lidar {
      translation 0.04 0 0.09
      children [
        Shape {
          appearance PBRAppearance {
            baseColor 0.5 0.5 0.5
            roughness 1
            metalness 0.5
          }
          geometry Cylinder {
            height 0.015
            radius 0.005
          }
        }
      ]
      name "top lidar"
      numberOfLayers 1
      maxRange 5
    }
    HingeJoint {
      jointParameters HingeJointParameters {
        axis 0 1 0
        anchor 0 0 0.025
      }
      device [
        RotationalMotor {
          name "left wheel motor"
        }
        PositionSensor {
          name "left wheel sensor"
          resolution 0.00628
        }
      ]
      endPoint Solid {
        translation 0 0.045 0.025
        children [
          DEF WHEEL Pose {
            rotation 1 0 0 1.5707996938995747
            children [
              Shape {
                appearance PBRAppearance {
                  baseColor 1 0 0
                  roughness 1
                  metalness 0
                }
                geometry Cylinder {
                  height 0.01
                  radius 0.025
                }
              }
            ]
          }
        ]
        name "left wheel"
        boundingObject USE WHEEL
        physics Physics {
        }
      }
    }
    HingeJoint {
      jointParameters HingeJointParameters {
        axis 0 1 0
        anchor 0 0 0.025
      }
      device [
        RotationalMotor {
          name "right wheel motor"
        }
        PositionSensor {
          name "right wheel sensor"
          resolution 0.00628
        }
      ]
      endPoint Solid {
        translation 0 -0.045 0.025
        children [
          USE WHEEL
        ]
        name "right wheel"
        boundingObject USE WHEEL
        physics Physics {
        }
      }
    }
    Pose {
      translation 0 0 0.0415
      children [
        Shape {
          appearance PBRAppearance {
            baseColor 0 0 1
            roughness 1
            metalness 0
          }
          geometry DEF BODY Cylinder {
            height 0.08
            radius 0.045
          }
        }
      ]
    }
    DistanceSensor {
      translation 0.042 0.02 0.063
      rotation 0 0 1 0.5236003061004253
      children [
        DEF SENSOR Pose {
          rotation 0 1 0 1.5708
          children [
            Shape {
              appearance PBRAppearance {
                baseColor 1 1 0
                roughness 1
                metalness 0
              }
              geometry Cylinder {
                height 0.004
                radius 0.008
              }
            }
          ]
        }
      ]
      name "ds0"
      lookupTable [
        0 1020 0
        0.05 1020 0
        0.15 0 0
      ]
      numberOfRays 2
      aperture 1
    }
    DistanceSensor {
      translation 0.042 -0.02 0.063
      rotation 0 0 1 -0.5235996938995747
      children [
        USE SENSOR
      ]
      name "ds1"
      lookupTable [
        0 1020 0
        0.05 1020 0
        0.15 0 0
      ]
      numberOfRays 2
      aperture 1
    }
  ]
  name "my_robot"
  boundingObject Pose {
    translation 0 0 0.0415
    children [
      USE BODY
    ]
  }
  physics Physics {
  }
  controller "<extern>"
}
Radiator {
  translation -4.99608e-07 2.85 0.3
  rotation 0 0 1 -1.5707953071795862
}
